Workbook

Sheet Instructions
A1: ហាងលក់ម៉ូតូ សេងតារា — Cost & Profit Tracker
A2: How to use this workbook / របៀបប្រើប្រាស់សៀវភៅនេះ
A6: Sheets in this workbook: / សន្លឹកនៅក្នុងសៀវភៅនេះ៖
A7: Dashboard | B7: Live snapshot: stock levels, cash tied up, total profit, and documents needing attention. / ទិដ្ឋភាពសង្ខេប៖ ស្តុក ដើមទុន ប្រាក់ចំណេញ និងឯកសារត្រូវការការយកចិត្តទុកដាក់។
A8: Vehicle Register | B8: The core sheet — one row per physical motorcycle, from the day you buy it to the day you sell it. / សន្លឹកសំខាន់ — មួយជួរសម្រាប់ម៉ូតូមួយគ្រឿង តាំងពីទិញរហូតដល់លក់។
A9: New Stock / Used Stock | B9: Automatic filtered views of Vehicle Register — read-only, split by condition. Edit in Vehicle Register; these update themselves. / ទិដ្ឋភាពដោយស្វ័យប្រវត្តិ បំបែកតាមលក្ខខណ្ឌ សូមកែសម្រួលនៅ Vehicle Register។
A10: Monthly Expenses | B10: Enter fixed running costs (rent, staff, utilities, marketing) per month. / បញ្ចូលចំណាយថេរប្រចាំខែ (ថ្លៃឈ្នួល ប្រាក់ខែ ទឹកភ្លើង ទីផ្សារ)។
A11: Profit Summary | B11: Automatic monthly report: revenue, cost of goods sold, gross profit, expenses, and net profit. / របាយការណ៍ប្រចាំខែស្វ័យប្រវត្តិ៖ ចំណូល ថ្លៃដើម ប្រាក់ចំណេញដុល ចំណាយ និងប្រាក់ចំណេញសុទ្ធ។
A13: Color legend: / និមិត្តសញ្ញាពណ៌៖
A15: Blue text / អក្សរខៀវ | B15: A cell you type into (cost, price, dates, engine/plate numbers, documents status). / ក្រឡាដែលអ្នកវាយបញ្ចូល។
A16: Black text / អក្សរខ្មៅ | B16: A formula — calculated automatically. Don't overwrite these. / រូបមន្តគណនាស្វ័យប្រវត្តិ សូមកុំកែ។
A17: Green text / អក្សរបៃតង | B17: A value pulled automatically from another sheet. / តម្លៃទាញយកពីសន្លឹកផ្សេងដោយស្វ័យប្រវត្តិ។
A18: Green fill / ពណ៌បៃតង | B18: In Stock, or Documents Complete. / នៅស្តុក ឬឯកសារពេញលេញ។
A19: Yellow fill / ពណ៌លឿង | B19: Documents Pending Transfer — needs follow-up. / កំពុងផ្ទេរឯកសារ — ត្រូវតាមដាន។
A20: Red fill / ពណ៌ក្រហម | B20: Documents Missing — needs urgent follow-up before resale. / ខ្វះឯកសារ — ត្រូវតាមដានបន្ទាន់មុនលក់។
A22: How the Vehicle Register works: / របៀបប្រើ Vehicle Register៖
A23: 1. When a motorcycle arrives (new from supplier, or used trade-in), add a new row: brand, model, engine number, chassis/frame number, plate number (if any), date bought in, purchase cost, and documents status. / នៅពេលម៉ូតូថ្មីមកដល់ សូមបន្ថែមជួរថ្មី៖ ម៉ាក ម៉ូដែល លេខម៉ាស៊ីន លេខគ្រោង លេខស្លាកលេខ ថ្ងៃទិញចូល ថ្លៃទិញ និងស្ថានភាពឯកសារ។
A24: 2. If it needs repair before resale, enter that cost in 'Repair Cost' — Total Cost updates automatically. / បើត្រូវជួសជុលមុនលក់ សូមបញ្ចូលថ្លៃជួសជុល — ថ្លៃសរុបនឹងគណនាដោយស្វ័យប្រវត្តិ។
A25: 3. Set Status to 'In Stock'. Change it to 'Reserved' once a customer commits, or 'Sold' once paid. / កំណត់ស្ថានភាពជា 'In Stock' ប្តូរទៅ 'Reserved' ឬ 'Sold' នៅពេលសមស្រប។
A26: 4. When sold, fill in Date Sold Out and Actual Sale Price. Profit and Margin calculate automatically. / នៅពេលលក់ សូមបញ្ចូលថ្ងៃលក់ចេញ និងតម្លៃលក់ពិត។ ប្រាក់ចំណេញនឹងគណនាដោយស្វ័យប្រវត្តិ។
A27: 5. Keep 'Owner Documents' updated — anything not 'Complete' is flagged in red/yellow so nothing slips through. / សូមធ្វើបច្ចុប្បន្នភាព 'ឯកសារម្ចាស់' ជានិច្ច។
A28: 6. Dashboard and Profit Summary update instantly from this sheet — no extra data entry needed. / Dashboard និង Profit Summary ធ្វើបច្ចុប្បន្នភាពភ្លាមៗ មិនចាំបាច់វាយបញ្ចូលបន្ថែមទេ។

Sheet Sheet

Sheet Vehicle Register
A1: Vehicle Register
A2: One row per physical motorcycle — the single source of truth from purchase to sale. / មួយជួរសម្រាប់ម៉ូតូមួយគ្រឿង តាំងពីទិញរហូតដល់លក់។
A4: Unit ID លេខរៀង | B4: Status ស្ថានភាព | C4: Condition លក្ខខណ្ឌ | D4: Brand ម៉ាក | E4: Model ម៉ូដែល | F4: Year ឆ្នាំ | G4: Color ពណ៌ | H4: Engine Number លេខម៉ាស៊ីន | I4: Chassis/Frame No. លេខគ្រោង | J4: Plate Number លេខស្លាកលេខ | K4: Date Bought In ថ្ងៃទិញចូល | L4: Purchase Cost ($) ថ្លៃទិញ ($) | M4: Repair Cost ($) ថ្លៃជួសជុល ($) | N4: Total Cost ($) ថ្លៃសរុប ($) | O4: Owner Documents ឯកសារម្ចាស់ | P4: Previous Owner ម្ចាស់មុន | Q4: Asking Price ($) តម្លៃលក់ ($) | R4: Date Sold Out ថ្ងៃលក់ចេញ | S4: Sale Price ($) តម្លៃលក់ពិត ($) | T4: Days in Stock ចំនួនថ្ងៃនៅស្តុក | U4: Profit ($) ប្រាក់ចំណេញ ($) | V4: Margin (%) អត្រាចំណេញ (%) | W4: Month Sold ខែលក់ (ស្វ័យប្រវត្តិ) | X4: New Rank (helper) | Y4: Used Rank (helper)
A5: RM-0001 | B5: Sold | C5: New | D5: Honda | E5: Honda Dream 125i | F5: 2026 | G5: Red | H5: JC52E-118820 | I5: MLHJC52E1P8118820 | J5: 2AA-1023 | K5: 46162 | L5: 1550 | M5: 0 | N5: =L5+M5 -> 1550 | O5: Complete | Q5: 1850 | R5: 46176 | S5: 1850 | T5: =IF(B5="Sold",R5-K5,TODAY()-K5) -> 14 | U5: =IF(B5="Sold",S5-N5,"") -> 300 | V5: =IF(B5="Sold",IFERROR(U5/S5,0),"") -> 0.16216216 | W5: =IF(B5="Sold",DATE(YEAR(R5),MONTH(R5),1),"") -> 46174 | X5: =IF(C5="New",COUNTIFS($C$5:C5,"New"),"") -> 1 | Y5: =IF(C5="Used",COUNTIFS($C$5:C5,"Used"),"")
A6: RM-0002 | B6: Sold | C6: New | D6: Honda | E6: Honda Wave 125i | F6: 2026 | G6: Black | H6: JA07E-220134 | I6: MLHJA07E2P8220134 | J6: 2AA-1045 | K6: 46164 | L6: 1450 | M6: 0 | N6: =L6+M6 -> 1450 | O6: Complete | Q6: 1750 | R6: 46183 | S6: 1750 | T6: =IF(B6="Sold",R6-K6,TODAY()-K6) -> 19 | U6: =IF(B6="Sold",S6-N6,"") -> 300 | V6: =IF(B6="Sold",IFERROR(U6/S6,0),"") -> 0.17142857 | W6: =IF(B6="Sold",DATE(YEAR(R6),MONTH(R6),1),"") -> 46174 | X6: =IF(C6="New",COUNTIFS($C$5:C6,"New"),"") -> 2 | Y6: =IF(C6="Used",COUNTIFS($C$5:C6,"Used"),"")
A7: RM-0003 | B7: Sold | C7: New | D7: Honda | E7: Honda Wave 125i | F7: 2026 | G7: Blue | H7: JA07E-220135 | I7: MLHJA07E2P8220135 | J7: 2AA-1046 | K7: 46164 | L7: 1450 | M7: 0 | N7: =L7+M7 -> 1450 | O7: Complete | Q7: 1750 | R7: 46183 | S7: 1750 | T7: =IF(B7="Sold",R7-K7,TODAY()-K7) -> 19 | U7: =IF(B7="Sold",S7-N7,"") -> 300 | V7: =IF(B7="Sold",IFERROR(U7/S7,0),"") -> 0.17142857 | W7: =IF(B7="Sold",DATE(YEAR(R7),MONTH(R7),1),"") -> 46174 | X7: =IF(C7="New",COUNTIFS($C$5:C7,"New"),"") -> 3 | Y7: =IF(C7="Used",COUNTIFS($C$5:C7,"Used"),"")
A8: RM-0004 | B8: Sold | C8: New | D8: Honda | E8: Honda Wave 125i | F8: 2026 | G8: Red | H8: JA07E-220136 | I8: MLHJA07E2P8220136 | J8: 2AA-1047 | K8: 46164 | L8: 1450 | M8: 0 | N8: =L8+M8 -> 1450 | O8: Complete | Q8: 1750 | R8: 46183 | S8: 1750 | T8: =IF(B8="Sold",R8-K8,TODAY()-K8) -> 19 | U8: =IF(B8="Sold",S8-N8,"") -> 300 | V8: =IF(B8="Sold",IFERROR(U8/S8,0),"") -> 0.17142857 | W8: =IF(B8="Sold",DATE(YEAR(R8),MONTH(R8),1),"") -> 46174 | X8: =IF(C8="New",COUNTIFS($C$5:C8,"New"),"") -> 4 | Y8: =IF(C8="Used",COUNTIFS($C$5:C8,"Used"),"")
A9: RM-0005 | B9: Sold | C9: New | D9: Honda | E9: Honda Click 125i | F9: 2026 | G9: White | H9: JF71E-330210 | I9: MLHJF71E3P8330210 | J9: 2AA-1058 | K9: 46167 | L9: 1750 | M9: 0 | N9: =L9+M9 -> 1750 | O9: Complete | Q9: 2100 | R9: 46191 | S9: 2100 | T9: =IF(B9="Sold",R9-K9,TODAY()-K9) -> 24 | U9: =IF(B9="Sold",S9-N9,"") -> 350 | V9: =IF(B9="Sold",IFERROR(U9/S9,0),"") -> 0.16666667 | W9: =IF(B9="Sold",DATE(YEAR(R9),MONTH(R9),1),"") -> 46174 | X9: =IF(C9="New",COUNTIFS($C$5:C9,"New"),"") -> 5 | Y9: =IF(C9="Used",COUNTIFS($C$5:C9,"Used"),"")
A10: RM-0006 | B10: Sold | C10: New | D10: Honda | E10: Honda Beat 110 | F10: 2026 | G10: Silver | H10: JB02E-440310 | I10: MLHJB02E4P8440310 | J10: 2AA-1061 | K10: 46170 | L10: 1300 | M10: 0 | N10: =L10+M10 -> 1300 | O10: Complete | Q10: 1600 | R10: 46198 | S10: 1600 | T10: =IF(B10="Sold",R10-K10,TODAY()-K10) -> 28 | U10: =IF(B10="Sold",S10-N10,"") -> 300 | V10: =IF(B10="Sold",IFERROR(U10/S10,0),"") -> 0.1875 | W10: =IF(B10="Sold",DATE(YEAR(R10),MONTH(R10),1),"") -> 46174 | X10: =IF(C10="New",COUNTIFS($C$5:C10,"New"),"") -> 6 | Y10: =IF(C10="Used",COUNTIFS($C$5:C10,"Used"),"")
A11: RM-0007 | B11: Sold | C11: New | D11: Honda | E11: Honda Beat 110 | F11: 2026 | G11: Black | H11: JB02E-440311 | I11: MLHJB02E4P8440311 | J11: 2AA-1062 | K11: 46170 | L11: 1300 | M11: 0 | N11: =L11+M11 -> 1300 | O11: Complete | Q11: 1600 | R11: 46198 | S11: 1600 | T11: =IF(B11="Sold",R11-K11,TODAY()-K11) -> 28 | U11: =IF(B11="Sold",S11-N11,"") -> 300 | V11: =IF(B11="Sold",IFERROR(U11/S11,0),"") -> 0.1875 | W11: =IF(B11="Sold",DATE(YEAR(R11),MONTH(R11),1),"") -> 46174 | X11: =IF(C11="New",COUNTIFS($C$5:C11,"New"),"") -> 7 | Y11: =IF(C11="Used",COUNTIFS($C$5:C11,"Used"),"")
A12: RM-0008 | B12: Sold | C12: New | D12: Honda | E12: Honda Scoopy i | F12: 2026 | G12: White | H12: JC30E-550402 | I12: MLHJC30E5P8550402 | J12: 2AA-1070 | K12: 46174 | L12: 1600 | M12: 0 | N12: =L12+M12 -> 1600 | O12: Complete | Q12: 1950 | R12: 46205 | S12: 1950 | T12: =IF(B12="Sold",R12-K12,TODAY()-K12) -> 31 | U12: =IF(B12="Sold",S12-N12,"") -> 350 | V12: =IF(B12="Sold",IFERROR(U12/S12,0),"") -> 0.17948718 | W12: =IF(B12="Sold",DATE(YEAR(R12),MONTH(R12),1),"") -> 46204 | X12: =IF(C12="New",COUNTIFS($C$5:C12,"New"),"") -> 8 | Y12: =IF(C12="Used",COUNTIFS($C$5:C12,"Used"),"")
A13: RM-0009 | B13: Sold | C13: New | D13: Honda | E13: Honda Scoopy i | F13: 2026 | G13: Pink | H13: JC30E-550403 | I13: MLHJC30E5P8550403 | J13: 2AA-1071 | K13: 46174 | L13: 1600 | M13: 0 | N13: =L13+M13 -> 1600 | O13: Complete | Q13: 1950 | R13: 46205 | S13: 1950 | T13: =IF(B13="Sold",R13-K13,TODAY()-K13) -> 31 | U13: =IF(B13="Sold",S13-N13,"") -> 350 | V13: =IF(B13="Sold",IFERROR(U13/S13,0),"") -> 0.17948718 | W13: =IF(B13="Sold",DATE(YEAR(R13),MONTH(R13),1),"") -> 46204 | X13: =IF(C13="New",COUNTIFS($C$5:C13,"New"),"") -> 9 | Y13: =IF(C13="Used",COUNTIFS($C$5:C13,"Used"),"")
A14: RM-0010 | B14: Sold | C14: New | D14: Honda | E14: Honda Future 125 | F14: 2026 | G14: Blue | H14: JD44E-660512 | I14: MLHJD44E6P8660512 | J14: 2AA-1080 | K14: 46176 | L14: 1580 | M14: 0 | N14: =L14+M14 -> 1580 | O14: Complete | Q14: 1900 | R14: 46212 | S14: 1900 | T14: =IF(B14="Sold",R14-K14,TODAY()-K14) -> 36 | U14: =IF(B14="Sold",S14-N14,"") -> 320 | V14: =IF(B14="Sold",IFERROR(U14/S14,0),"") -> 0.16842105 | W14: =IF(B14="Sold",DATE(YEAR(R14),MONTH(R14),1),"") -> 46204 | X14: =IF(C14="New",COUNTIFS($C$5:C14,"New"),"") -> 10 | Y14: =IF(C14="Used",COUNTIFS($C$5:C14,"Used"),"")
A15: RM-0011 | B15: Sold | C15: Used | D15: Honda | E15: Honda Dream 125i | F15: 2021 | G15: Red | H15: JC52E-098213 | I15: MLHJC52E1M8098213 | J15: 2AB-4410 | K15: 46178 | L15: 1150 | M15: 120 | N15: =L15+M15 -> 1270 | O15: Complete | P15: Sok Dara | Q15: 1500 | R15: 46218 | S15: 1450 | T15: =IF(B15="Sold",R15-K15,TODAY()-K15) -> 40 | U15: =IF(B15="Sold",S15-N15,"") -> 180 | V15: =IF(B15="Sold",IFERROR(U15/S15,0),"") -> 0.12413793 | W15: =IF(B15="Sold",DATE(YEAR(R15),MONTH(R15),1),"") -> 46204 | X15: =IF(C15="New",COUNTIFS($C$5:C15,"New"),"") | Y15: =IF(C15="Used",COUNTIFS($C$5:C15,"Used"),"") -> 1
A16: RM-0012 | B16: Sold | C16: Used | D16: Honda | E16: Honda Dream 125i | F16: 2021 | G16: Blue | H16: JC52E-098214 | I16: MLHJC52E1M8098214 | J16: 2AB-4411 | K16: 46181 | L16: 1150 | M16: 150 | N16: =L16+M16 -> 1300 | O16: Complete | P16: Chan Vuthy | Q16: 1550 | R16: 46218 | S16: 1500 | T16: =IF(B16="Sold",R16-K16,TODAY()-K16) -> 37 | U16: =IF(B16="Sold",S16-N16,"") -> 200 | V16: =IF(B16="Sold",IFERROR(U16/S16,0),"") -> 0.13333333 | W16: =IF(B16="Sold",DATE(YEAR(R16),MONTH(R16),1),"") -> 46204 | X16: =IF(C16="New",COUNTIFS($C$5:C16,"New"),"") | Y16: =IF(C16="Used",COUNTIFS($C$5:C16,"Used"),"") -> 2
A17: RM-0013 | B17: Sold | C17: Used | D17: Honda | E17: Honda Dream 125i | F17: 2020 | G17: Black | H17: JC52E-087102 | I17: MLHJC52E1L8087102 | J17: 2AB-4390 | K17: 46183 | L17: 1050 | M17: 200 | N17: =L17+M17 -> 1250 | O17: Pending Transfer | P17: Heng Sopheak | Q17: 1450 | R17: 46218 | S17: 1400 | T17: =IF(B17="Sold",R17-K17,TODAY()-K17) -> 35 | U17: =IF(B17="Sold",S17-N17,"") -> 150 | V17: =IF(B17="Sold",IFERROR(U17/S17,0),"") -> 0.10714286 | W17: =IF(B17="Sold",DATE(YEAR(R17),MONTH(R17),1),"") -> 46204 | X17: =IF(C17="New",COUNTIFS($C$5:C17,"New"),"") | Y17: =IF(C17="Used",COUNTIFS($C$5:C17,"Used"),"") -> 3
A18: RM-0014 | B18: Sold | C18: New | D18: Yamaha | E18: Yamaha NMAX 155 | F18: 2026 | G18: Gray | H18: 2DP-005521 | I18: MH32DP005TK005521 | J18: 2AA-1102 | K18: 46185 | L18: 3050 | M18: 0 | N18: =L18+M18 -> 3050 | O18: Complete | Q18: 3600 | R18: 46225 | S18: 3600 | T18: =IF(B18="Sold",R18-K18,TODAY()-K18) -> 40 | U18: =IF(B18="Sold",S18-N18,"") -> 550 | V18: =IF(B18="Sold",IFERROR(U18/S18,0),"") -> 0.15277778 | W18: =IF(B18="Sold",DATE(YEAR(R18),MONTH(R18),1),"") -> 46204 | X18: =IF(C18="New",COUNTIFS($C$5:C18,"New"),"") -> 11 | Y18: =IF(C18="Used",COUNTIFS($C$5:C18,"Used"),"")
A19: RM-0015 | B19: Sold | C19: Used | D19: Honda | E19: Honda Wave 125i | F19: 2020 | G19: Red | H19: JA07E-198832 | I19: MLHJA07E2L8198832 | J19: 2AB-3320 | K19: 46188 | L19: 920 | M19: 80 | N19: =L19+M19 -> 1000 | O19: Complete | P19: Ly Sreymom | Q19: 1250 | R19: 46231 | S19: 1250 | T19: =IF(B19="Sold",R19-K19,TODAY()-K19) -> 43 | U19: =IF(B19="Sold",S19-N19,"") -> 250 | V19: =IF(B19="Sold",IFERROR(U19/S19,0),"") -> 0.2 | W19: =IF(B19="Sold",DATE(YEAR(R19),MONTH(R19),1),"") -> 46204 | X19: =IF(C19="New",COUNTIFS($C$5:C19,"New"),"") | Y19: =IF(C19="Used",COUNTIFS($C$5:C19,"Used"),"") -> 4
A20: RM-0016 | B20: Sold | C20: Used | D20: Honda | E20: Honda Wave 125i | F20: 2019 | G20: Blue | H20: JA07E-176621 | I20: MLHJA07E2K8176621 | J20: 2AB-3298 | K20: 46191 | L20: 920 | M20: 110 | N20: =L20+M20 -> 1030 | O20: Missing Documents | P20: Un Bunthoeun | Q20: 1200 | R20: 46231 | S20: 1150 | T20: =IF(B20="Sold",R20-K20,TODAY()-K20) -> 40 | U20: =IF(B20="Sold",S20-N20,"") -> 120 | V20: =IF(B20="Sold",IFERROR(U20/S20,0),"") -> 0.10434783 | W20: =IF(B20="Sold",DATE(YEAR(R20),MONTH(R20),1),"") -> 46204 | X20: =IF(C20="New",COUNTIFS($C$5:C20,"New"),"") | Y20: =IF(C20="Used",COUNTIFS($C$5:C20,"Used"),"") -> 5
A21: RM-0017 | B21: Sold | C21: New | D21: Honda | E21: Honda Air Blade 125 | F21: 2026 | G21: Matte Black | H21: JG10E-770601 | I21: MLHJG10E7P8770601 | J21: 2AA-1130 | K21: 46204 | L21: 2050 | M21: 0 | N21: =L21+M21 -> 2050 | O21: Complete | Q21: 2450 | R21: 46238 | S21: 2450 | T21: =IF(B21="Sold",R21-K21,TODAY()-K21) -> 34 | U21: =IF(B21="Sold",S21-N21,"") -> 400 | V21: =IF(B21="Sold",IFERROR(U21/S21,0),"") -> 0.16326531 | W21: =IF(B21="Sold",DATE(YEAR(R21),MONTH(R21),1),"") -> 46235 | X21: =IF(C21="New",COUNTIFS($C$5:C21,"New"),"") -> 12 | Y21: =IF(C21="Used",COUNTIFS($C$5:C21,"Used"),"")
A22: RM-0018 | B22: Sold | C22: New | D22: Honda | E22: Honda Click 125i | F22: 2026 | G22: Red | H22: JF71E-330211 | I22: MLHJF71E3P8330211 | J22: 2AA-1141 | K22: 46206 | L22: 1750 | M22: 0 | N22: =L22+M22 -> 1750 | O22: Complete | Q22: 2100 | R22: 46245 | S22: 2100 | T22: =IF(B22="Sold",R22-K22,TODAY()-K22) -> 39 | U22: =IF(B22="Sold",S22-N22,"") -> 350 | V22: =IF(B22="Sold",IFERROR(U22/S22,0),"") -> 0.16666667 | W22: =IF(B22="Sold",DATE(YEAR(R22),MONTH(R22),1),"") -> 46235 | X22: =IF(C22="New",COUNTIFS($C$5:C22,"New"),"") -> 13 | Y22: =IF(C22="Used",COUNTIFS($C$5:C22,"Used"),"")
A23: RM-0019 | B23: Sold | C23: New | D23: Honda | E23: Honda Click 125i | F23: 2026 | G23: Black | H23: JF71E-330212 | I23: MLHJF71E3P8330212 | J23: 2AA-1142 | K23: 46206 | L23: 1750 | M23: 0 | N23: =L23+M23 -> 1750 | O23: Complete | Q23: 2100 | R23: 46245 | S23: 2100 | T23: =IF(B23="Sold",R23-K23,TODAY()-K23) -> 39 | U23: =IF(B23="Sold",S23-N23,"") -> 350 | V23: =IF(B23="Sold",IFERROR(U23/S23,0),"") -> 0.16666667 | W23: =IF(B23="Sold",DATE(YEAR(R23),MONTH(R23),1),"") -> 46235 | X23: =IF(C23="New",COUNTIFS($C$5:C23,"New"),"") -> 14 | Y23: =IF(C23="Used",COUNTIFS($C$5:C23,"Used"),"")
A24: RM-0020 | B24: Sold | C24: New | D24: Honda | E24: Honda Vario 125 | F24: 2026 | G24: White | H24: JH22E-880711 | I24: MLHJH22E8P8880711 | J24: 2AA-1150 | K24: 46208 | L24: 1850 | M24: 0 | N24: =L24+M24 -> 1850 | O24: Complete | Q24: 2200 | R24: 46252 | S24: 2200 | T24: =IF(B24="Sold",R24-K24,TODAY()-K24) -> 44 | U24: =IF(B24="Sold",S24-N24,"") -> 350 | V24: =IF(B24="Sold",IFERROR(U24/S24,0),"") -> 0.15909091 | W24: =IF(B24="Sold",DATE(YEAR(R24),MONTH(R24),1),"") -> 46235 | X24: =IF(C24="New",COUNTIFS($C$5:C24,"New"),"") -> 15 | Y24: =IF(C24="Used",COUNTIFS($C$5:C24,"Used"),"")
A25: RM-0021 | B25: Sold | C25: New | D25: Royal Enfield | E25: Royal Enfield Hunter 350 | F25: 2026 | G25: Black | H25: RE350-991201 | I25: MEE350RE1P8991201 | J25: 2AA-1160 | K25: 46213 | L25: 3350 | M25: 0 | N25: =L25+M25 -> 3350 | O25: Complete | Q25: 4000 | R25: 46258 | S25: 4000 | T25: =IF(B25="Sold",R25-K25,TODAY()-K25) -> 45 | U25: =IF(B25="Sold",S25-N25,"") -> 650 | V25: =IF(B25="Sold",IFERROR(U25/S25,0),"") -> 0.1625 | W25: =IF(B25="Sold",DATE(YEAR(R25),MONTH(R25),1),"") -> 46235 | X25: =IF(C25="New",COUNTIFS($C$5:C25,"New"),"") -> 16 | Y25: =IF(C25="Used",COUNTIFS($C$5:C25,"Used"),"")
A26: RM-0022 | B26: In Stock | C26: New | D26: Honda | E26: Honda Dream 125i | F26: 2026 | G26: Red | H26: JC52E-118825 | I26: MLHJC52E1P8118825 | K26: 46235 | L26: 1550 | M26: 0 | N26: =L26+M26 -> 1550 | O26: Complete | Q26: 1850 | T26: =IF(B26="Sold",R26-K26,TODAY()-K26) -> 27 | U26: =IF(B26="Sold",S26-N26,"") | V26: =IF(B26="Sold",IFERROR(U26/S26,0),"") | W26: =IF(B26="Sold",DATE(YEAR(R26),MONTH(R26),1),"") | X26: =IF(C26="New",COUNTIFS($C$5:C26,"New"),"") -> 17 | Y26: =IF(C26="Used",COUNTIFS($C$5:C26,"Used"),"")
A27: RM-0023 | B27: In Stock | C27: New | D27: Honda | E27: Honda Wave 125i | F27: 2026 | G27: Black | H27: JA07E-220140 | I27: MLHJA07E2P8220140 | K27: 46237 | L27: 1450 | M27: 0 | N27: =L27+M27 -> 1450 | O27: Complete | Q27: 1750 | T27: =IF(B27="Sold",R27-K27,TODAY()-K27) -> 25 | U27: =IF(B27="Sold",S27-N27,"") | V27: =IF(B27="Sold",IFERROR(U27/S27,0),"") | W27: =IF(B27="Sold",DATE(YEAR(R27),MONTH(R27),1),"") | X27: =IF(C27="New",COUNTIFS($C$5:C27,"New"),"") -> 18 | Y27: =IF(C27="Used",COUNTIFS($C$5:C27,"Used"),"")
A28: RM-0024 | B28: In Stock | C28: New | D28: Honda | E28: Honda Click 125i | F28: 2026 | G28: White | H28: JF71E-330220 | I28: MLHJF71E3P8330220 | K28: 46239 | L28: 1750 | M28: 0 | N28: =L28+M28 -> 1750 | O28: Complete | Q28: 2100 | T28: =IF(B28="Sold",R28-K28,TODAY()-K28) -> 23 | U28: =IF(B28="Sold",S28-N28,"") | V28: =IF(B28="Sold",IFERROR(U28/S28,0),"") | W28: =IF(B28="Sold",DATE(YEAR(R28),MONTH(R28),1),"") | X28: =IF(C28="New",COUNTIFS($C$5:C28,"New"),"") -> 19 | Y28: =IF(C28="Used",COUNTIFS($C$5:C28,"Used"),"")
A29: RM-0025 | B29: In Stock | C29: Used | D29: Honda | E29: Honda Future 125 | F29: 2019 | G29: Silver | H29: JD44E-541203 | I29: MLHJD44E6L8541203 | J29: 2AB-2201 | K29: 46244 | L29: 1000 | M29: 180 | N29: =L29+M29 -> 1180 | O29: Pending Transfer | P29: Prom Kimheng | Q29: 1350 | T29: =IF(B29="Sold",R29-K29,TODAY()-K29) -> 18 | U29: =IF(B29="Sold",S29-N29,"") | V29: =IF(B29="Sold",IFERROR(U29/S29,0),"") | W29: =IF(B29="Sold",DATE(YEAR(R29),MONTH(R29),1),"") | X29: =IF(C29="New",COUNTIFS($C$5:C29,"New"),"") | Y29: =IF(C29="Used",COUNTIFS($C$5:C29,"Used"),"") -> 6
A30: RM-0026 | B30: In Stock | C30: New | D30: Honda | E30: Honda Beat 110 | F30: 2026 | G30: White | H30: JB02E-440320 | I30: MLHJB02E4P8440320 | K30: 46246 | L30: 1300 | M30: 0 | N30: =L30+M30 -> 1300 | O30: Complete | Q30: 1600 | T30: =IF(B30="Sold",R30-K30,TODAY()-K30) -> 16 | U30: =IF(B30="Sold",S30-N30,"") | V30: =IF(B30="Sold",IFERROR(U30/S30,0),"") | W30: =IF(B30="Sold",DATE(YEAR(R30),MONTH(R30),1),"") | X30: =IF(C30="New",COUNTIFS($C$5:C30,"New"),"") -> 20 | Y30: =IF(C30="Used",COUNTIFS($C$5:C30,"Used"),"")
A31: RM-0027 | B31: In Stock | C31: Used | D31: Honda | E31: Honda Click 125i | F31: 2021 | G31: Blue | H31: JF71E-221044 | I31: MLHJF71E3M8221044 | J31: 2AB-4502 | K31: 46249 | L31: 1180 | M31: 90 | N31: =L31+M31 -> 1270 | O31: Missing Documents | P31: Vann Chenda | Q31: 1550 | T31: =IF(B31="Sold",R31-K31,TODAY()-K31) -> 13 | U31: =IF(B31="Sold",S31-N31,"") | V31: =IF(B31="Sold",IFERROR(U31/S31,0),"") | W31: =IF(B31="Sold",DATE(YEAR(R31),MONTH(R31),1),"") | X31: =IF(C31="New",COUNTIFS($C$5:C31,"New"),"") | Y31: =IF(C31="Used",COUNTIFS($C$5:C31,"Used"),"") -> 7
A32: RM-0028 | B32: In Stock | C32: New | D32: Honda | E32: Honda Air Blade 125 | F32: 2026 | G32: White | H32: JG10E-770610 | I32: MLHJG10E7P8770610 | K32: 46252 | L32: 2050 | M32: 0 | N32: =L32+M32 -> 2050 | O32: Complete | Q32: 2450 | T32: =IF(B32="Sold",R32-K32,TODAY()-K32) -> 10 | U32: =IF(B32="Sold",S32-N32,"") | V32: =IF(B32="Sold",IFERROR(U32/S32,0),"") | W32: =IF(B32="Sold",DATE(YEAR(R32),MONTH(R32),1),"") | X32: =IF(C32="New",COUNTIFS($C$5:C32,"New"),"") -> 21 | Y32: =IF(C32="Used",COUNTIFS($C$5:C32,"Used"),"")
A33: RM-0029 | B33: Reserved | C33: New | D33: Honda | E33: Honda Vario 125 | F33: 2026 | G33: Black | H33: JH22E-880720 | I33: MLHJH22E8P8880720 | K33: 46254 | L33: 1850 | M33: 0 | N33: =L33+M33 -> 1850 | O33: Complete | Q33: 2200 | T33: =IF(B33="Sold",R33-K33,TODAY()-K33) -> 8 | U33: =IF(B33="Sold",S33-N33,"") | V33: =IF(B33="Sold",IFERROR(U33/S33,0),"") | W33: =IF(B33="Sold",DATE(YEAR(R33),MONTH(R33),1),"") | X33: =IF(C33="New",COUNTIFS($C$5:C33,"New"),"") -> 22 | Y33: =IF(C33="Used",COUNTIFS($C$5:C33,"Used"),"")
A34: RM-0030 | B34: In Stock | C34: New | D34: Yamaha | E34: Yamaha Sniper 125 | F34: 2026 | G34: Red | H34: B4T-113322 | I34: MH3B4T001TK113322 | K34: 46256 | L34: 1850 | M34: 0 | N34: =L34+M34 -> 1850 | O34: Complete | Q34: 2200 | T34: =IF(B34="Sold",R34-K34,TODAY()-K34) -> 6 | U34: =IF(B34="Sold",S34-N34,"") | V34: =IF(B34="Sold",IFERROR(U34/S34,0),"") | W34: =IF(B34="Sold",DATE(YEAR(R34),MONTH(R34),1),"") | X34: =IF(C34="New",COUNTIFS($C$5:C34,"New"),"") -> 23 | Y34: =IF(C34="Used",COUNTIFS($C$5:C34,"Used"),"")
A36: Add new units in new rows above row 500. Status/Condition/Owner Documents are dropdowns — click the cell and use the arrow. / បន្ថែមម៉ូតូថ្មីនៅជួរខាងលើជួរទី៥០០។ ស្ថានភាព/លក្ខខណ្ឌ/ឯកសារម្ចាស់ជាបញ្ជីទាញចុះ។

Sheet New Stock
A1: New Stock
A2: Automatic view of every 'New' unit — pulled live from Vehicle Register. Don't type here; edit in Vehicle Register instead. / បង្ហាញដោយស្វ័យប្រវត្តិ សូមកែសម្រួលនៅ Vehicle Register។
A4: Unit ID លេខរៀង | B4: Status ស្ថានភាព | C4: Condition លក្ខខណ្ឌ | D4: Brand ម៉ាក | E4: Model ម៉ូដែល | F4: Year ឆ្នាំ | G4: Color ពណ៌ | H4: Engine Number លេខម៉ាស៊ីន | I4: Chassis/Frame No. លេខគ្រោង | J4: Plate Number លេខស្លាកលេខ | K4: Date Bought In ថ្ងៃទិញចូល | L4: Purchase Cost ($) ថ្លៃទិញ ($) | M4: Repair Cost ($) ថ្លៃជួសជុល ($) | N4: Total Cost ($) ថ្លៃសរុប ($) | O4: Owner Documents ឯកសារម្ចាស់ | P4: Previous Owner ម្ចាស់មុន | Q4: Asking Price ($) តម្លៃលក់ ($) | R4: Date Sold Out ថ្ងៃលក់ចេញ | S4: Sale Price ($) តម្លៃលក់ពិត ($) | T4: Days in Stock ចំនួនថ្ងៃនៅស្តុក | U4: Profit ($) ប្រាក់ចំណេញ ($) | V4: Margin (%) អត្រាចំណេញ (%) | W4: Month Sold ខែលក់ (ស្វ័យប្រវត្តិ)
A5: =IFERROR(INDEX('Vehicle Register'!$A$5:$A$500, MATCH(1, 'Vehicle Register'!$X$5:$X$500, 0)), "") -> RM-0001 | B5: =IFERROR(INDEX('Vehicle Register'!$B$5:$B$500, MATCH(1, 'Vehicle Register'!$X$5:$X$500, 0)), "") -> Sold | C5: =IFERROR(INDEX('Vehicle Register'!$C$5:$C$500, MATCH(1, 'Vehicle Register'!$X$5:$X$500, 0)), "") -> New | D5: =IFERROR(INDEX('Vehicle Register'!$D$5:$D$500, MATCH(1, 'Vehicle Register'!$X$5:$X$500, 0)), "") -> Honda | E5: =IFERROR(INDEX('Vehicle Register'!$E$5:$E$500, MATCH(1, 'Vehicle Register'!$X$5:$X$500, 0)), "") -> Honda Dream 125i | F5: =IFERROR(INDEX('Vehicle Register'!$F$5:$F$500, MATCH(1, 'Vehicle Register'!$X$5:$X$500, 0)), "") -> 2026 | G5: =IFERROR(INDEX('Vehicle Register'!$G$5:$G$500, MATCH(1, 'Vehicle Register'!$X$5:$X$500, 0)), "") -> Red | H5: =IFERROR(INDEX('Vehicle Register'!$H$5:$H$500, MATCH(1, 'Vehicle Register'!$X$5:$X$500, 0)), "") -> JC52E-118820 | I5: =IFERROR(INDEX('Vehicle Register'!$I$5:$I$500, MATCH(1, 'Vehicle Register'!$X$5:$X$500, 0)), "") -> MLHJC52E1P8118820 | J5: =IFERROR(INDEX('Vehicle Register'!$J$5:$J$500, MATCH(1, 'Vehicle Register'!$X$5:$X$500, 0)), "") -> 2AA-1023 | K5: =IFERROR(INDEX('Vehicle Register'!$K$5:$K$500, MATCH(1, 'Vehicle Register'!$X$5:$X$500, 0)), "") -> 46162 | L5: =IFERROR(INDEX('Vehicle Register'!$L$5:$L$500, MATCH(1, 'Vehicle Register'!$X$5:$X$500, 0)), "") -> 1550 | M5: =IFERROR(INDEX('Vehicle Register'!$M$5:$M$500, MATCH(1, 'Vehicle Register'!$X$5:$X$500, 0)), "") -> 0 | N5: =IFERROR(INDEX('Vehicle Register'!$N$5:$N$500, MATCH(1, 'Vehicle Register'!$X$5:$X$500, 0)), "") -> 1550 | O5: =IFERROR(INDEX('Vehicle Register'!$O$5:$O$500, MATCH(1, 'Vehicle Register'!$X$5:$X$500, 0)), "") -> Complete | P5: =IFERROR(INDEX('Vehicle Register'!$P$5:$P$500, MATCH(1, 'Vehicle Register'!$X$5:$X$500, 0)), "") -> 0 | Q5: =IFERROR(INDEX('Vehicle Register'!$Q$5:$Q$500, MATCH(1, 'Vehicle Register'!$X$5:$X$500, 0)), "") -> 1850 | R5: =IFERROR(INDEX('Vehicle Register'!$R$5:$R$500, MATCH(1, 'Vehicle Register'!$X$5:$X$500, 0)), "") -> 46176 | S5: =IFERROR(INDEX('Vehicle Register'!$S$5:$S$500, MATCH(1, 'Vehicle Register'!$X$5:$X$500, 0)), "") -> 1850 | T5: =IFERROR(INDEX('Vehicle Register'!$T$5:$T$500, MATCH(1, 'Vehicle Register'!$X$5:$X$500, 0)), "") -> 14 | U5: =IFERROR(INDEX('Vehicle Register'!$U$5:$U$500, MATCH(1, 'Vehicle Register'!$X$5:$X$500, 0)), "") -> 300 | V5: =IFERROR(INDEX('Vehicle Register'!$V$5:$V$500, MATCH(1, 'Vehicle Register'!$X$5:$X$500, 0)), "") -> 0.16216216 | W5: =IFERROR(INDEX('Vehicle Register'!$W$5:$W$500, MATCH(1, 'Vehicle Register'!$X$5:$X$500, 0)), "") -> 46174
A6: =IFERROR(INDEX('Vehicle Register'!$A$5:$A$500, MATCH(2, 'Vehicle Register'!$X$5:$X$500, 0)), "") -> RM-0002 | B6: =IFERROR(INDEX('Vehicle Register'!$B$5:$B$500, MATCH(2, 'Vehicle Register'!$X$5:$X$500, 0)), "") -> Sold | C6: =IFERROR(INDEX('Vehicle Register'!$C$5:$C$500, MATCH(2, 'Vehicle Register'!$X$5:$X$500, 0)), "") -> New | D6: =IFERROR(INDEX('Vehicle Register'!$D$5:$D$500, MATCH(2, 'Vehicle Register'!$X$5:$X$500, 0)), "") -> Honda | E6: =IFERROR(INDEX('Vehicle Register'!$E$5:$E$500, MATCH(2, 'Vehicle Register'!$X$5:$X$500, 0)), "") -> Honda Wave 125i | F6: =IFERROR(INDEX('Vehicle Register'!$F$5:$F$500, MATCH(2, 'Vehicle Register'!$X$5:$X$500, 0)), "") -> 2026 | G6: =IFERROR(INDEX('Vehicle Register'!$G$5:$G$500, MATCH(2, 'Vehicle Register'!$X$5:$X$500, 0)), "") -> Black | H6: =IFERROR(INDEX('Vehicle Register'!$H$5:$H$500, MATCH(2, 'Vehicle Register'!$X$5:$X$500, 0)), "") -> JA07E-220134 | I6: =IFERROR(INDEX('Vehicle Register'!$I$5:$I$500, MATCH(2, 'Vehicle Register'!$X$5:$X$500, 0)), "") -> MLHJA07E2P8220134 | J6: =IFERROR(INDEX('Vehicle Register'!$J$5:$J$500, MATCH(2, 'Vehicle Register'!$X$5:$X$500, 0)), "") -> 2AA-1045 | K6: =IFERROR(INDEX('Vehicle Register'!$K$5:$K$500, MATCH(2, 'Vehicle Register'!$X$5:$X$500, 0)), "") -> 46164 | L6: =IFERROR(INDEX('Vehicle Register'!$L$5:$L$500, MATCH(2, 'Vehicle Register'!$X$5:$X$500, 0)), "") -> 1450 | M6: =IFERROR(INDEX('Vehicle Register'!$M$5:$M$500, MATCH(2, 'Vehicle Register'!$X$5:$X$500, 0)), "") -> 0 | N6: =IFERROR(INDEX('Vehicle Register'!$N$5:$N$500, MATCH(2, 'Vehicle Register'!$X$5:$X$500, 0)), "") -> 1450 | O6: =IFERROR(INDEX('Vehicle Register'!$O$5:$O$500, MATCH(2, 'Vehicle Register'!$X$5:$X$500, 0)), "") -> Complete | P6: =IFERROR(INDEX('Vehicle Register'!$P$5:$P$500, MATCH(2, 'Vehicle Register'!$X$5:$X$500, 0)), "") -> 0 | Q6: =IFERROR(INDEX('Vehicle Register'!$Q$5:$Q$500, MATCH(2, 'Vehicle Register'!$X$5:$X$500, 0)), "") -> 1750 | R6: =IFERROR(INDEX('Vehicle Register'!$R$5:$R$500, MATCH(2, 'Vehicle Register'!$X$5:$X$500, 0)), "") -> 46183 | S6: =IFERROR(INDEX('Vehicle Register'!$S$5:$S$500, MATCH(2, 'Vehicle Register'!$X$5:$X$500, 0)), "") -> 1750 | T6: =IFERROR(INDEX('Vehicle Register'!$T$5:$T$500, MATCH(2, 'Vehicle Register'!$X$5:$X$500, 0)), "") -> 19 | U6: =IFERROR(INDEX('Vehicle Register'!$U$5:$U$500, MATCH(2, 'Vehicle Register'!$X$5:$X$500, 0)), "") -> 300 | V6: =IFERROR(INDEX('Vehicle Register'!$V$5:$V$500, MATCH(2, 'Vehicle Register'!$X$5:$X$500, 0)), "") -> 0.17142857 | W6: =IFERROR(INDEX('Vehicle Register'!$W$5:$W$500, MATCH(2, 'Vehicle Register'!$X$5:$X$500, 0)), "") -> 46174
A7: =IFERROR(INDEX('Vehicle Register'!$A$5:$A$500, MATCH(3, 'Vehicle Register'!$X$5:$X$500, 0)), "") -> RM-0003 | B7: =IFERROR(INDEX('Vehicle Register'!$B$5:$B$500, MATCH(3, 'Vehicle Register'!$X$5:$X$500, 0)), "") -> Sold | C7: =IFERROR(INDEX('Vehicle Register'!$C$5:$C$500, MATCH(3, 'Vehicle Register'!$X$5:$X$500, 0)), "") -> New | D7: =IFERROR(INDEX('Vehicle Register'!$D$5:$D$500, MATCH(3, 'Vehicle Register'!$X$5:$X$500, 0)), "") -> Honda | E7: =IFERROR(INDEX('Vehicle Register'!$E$5:$E$500, MATCH(3, 'Vehicle Register'!$X$5:$X$500, 0)), "") -> Honda Wave 125i | F7: =IFERROR(INDEX('Vehicle Register'!$F$5:$F$500, MATCH(3, 'Vehicle Register'!$X$5:$X$500, 0)), "") -> 2026 | G7: =IFERROR(INDEX('Vehicle Register'!$G$5:$G$500, MATCH(3, 'Vehicle Register'!$X$5:$X$500, 0)), "") -> Blue | H7: =IFERROR(INDEX('Vehicle Register'!$H$5:$H$500, MATCH(3, 'Vehicle Register'!$X$5:$X$500, 0)), "") -> JA07E-220135 | I7: =IFERROR(INDEX('Vehicle Register'!$I$5:$I$500, MATCH(3, 'Vehicle Register'!$X$5:$X$500, 0)), "") -> MLHJA07E2P8220135 | J7: =IFERROR(INDEX('Vehicle Register'!$J$5:$J$500, MATCH(3, 'Vehicle Register'!$X$5:$X$500, 0)), "") -> 2AA-1046 | K7: =IFERROR(INDEX('Vehicle Register'!$K$5:$K$500, MATCH(3, 'Vehicle Register'!$X$5:$X$500, 0)), "") -> 46164 | L7: =IFERROR(INDEX('Vehicle Register'!$L$5:$L$500, MATCH(3, 'Vehicle Register'!$X$5:$X$500, 0)), "") -> 1450 | M7: =IFERROR(INDEX('Vehicle Register'!$M$5:$M$500, MATCH(3, 'Vehicle Register'!$X$5:$X$500, 0)), "") -> 0 | N7: =IFERROR(INDEX('Vehicle Register'!$N$5:$N$500, MATCH(3, 'Vehicle Register'!$X$5:$X$500, 0)), "") -> 1450 | O7: =IFERROR(INDEX('Vehicle Register'!$O$5:$O$500, MATCH(3, 'Vehicle Register'!$X$5:$X$500, 0)), "") -> Complete | P7: =IFERROR(INDEX('Vehicle Register'!$P$5:$P$500, MATCH(3, 'Vehicle Register'!$X$5:$X$500, 0)), "") -> 0 | Q7: =IFERROR(INDEX('Vehicle Register'!$Q$5:$Q$500, MATCH(3, 'Vehicle Register'!$X$5:$X$500, 0)), "") -> 1750 | R7: =IFERROR(INDEX('Vehicle Register'!$R$5:$R$500, MATCH(3, 'Vehicle Register'!$X$5:$X$500, 0)), "") -> 46183 | S7: =IFERROR(INDEX('Vehicle Register'!$S$5:$S$500, MATCH(3, 'Vehicle Register'!$X$5:$X$500, 0)), "") -> 1750 | T7: =IFERROR(INDEX('Vehicle Register'!$T$5:$T$500, MATCH(3, 'Vehicle Register'!$X$5:$X$500, 0)), "") -> 19 | U7: =IFERROR(INDEX('Vehicle Register'!$U$5:$U$500, MATCH(3, 'Vehicle Register'!$X$5:$X$500, 0)), "") -> 300 | V7: =IFERROR(INDEX('Vehicle Register'!$V$5:$V$500, MATCH(3, 'Vehicle Register'!$X$5:$X$500, 0)), "") -> 0.17142857 | W7: =IFERROR(INDEX('Vehicle Register'!$W$5:$W$500, MATCH(3, 'Vehicle Register'!$X$5:$X$500, 0)), "") -> 46174
A8: =IFERROR(INDEX('Vehicle Register'!$A$5:$A$500, MATCH(4, 'Vehicle Register'!$X$5:$X$500, 0)), "") -> RM-0004 | B8: =IFERROR(INDEX('Vehicle Register'!$B$5:$B$500, MATCH(4, 'Vehicle Register'!$X$5:$X$500, 0)), "") -> Sold | C8: =IFERROR(INDEX('Vehicle Register'!$C$5:$C$500, MATCH(4, 'Vehicle Register'!$X$5:$X$500, 0)), "") -> New | D8: =IFERROR(INDEX('Vehicle Register'!$D$5:$D$500, MATCH(4, 'Vehicle Register'!$X$5:$X$500, 0)), "") -> Honda | E8: =IFERROR(INDEX('Vehicle Register'!$E$5:$E$500, MATCH(4, 'Vehicle Register'!$X$5:$X$500, 0)), "") -> Honda Wave 125i | F8: =IFERROR(INDEX('Vehicle Register'!$F$5:$F$500, MATCH(4, 'Vehicle Register'!$X$5:$X$500, 0)), "") -> 2026 | G8: =IFERROR(INDEX('Vehicle Register'!$G$5:$G$500, MATCH(4, 'Vehicle Register'!$X$5:$X$500, 0)), "") -> Red | H8: =IFERROR(INDEX('Vehicle Register'!$H$5:$H$500, MATCH(4, 'Vehicle Register'!$X$5:$X$500, 0)), "") -> JA07E-220136 | I8: =IFERROR(INDEX('Vehicle Register'!$I$5:$I$500, MATCH(4, 'Vehicle Register'!$X$5:$X$500, 0)), "") -> MLHJA07E2P8220136 | J8: =IFERROR(INDEX('Vehicle Register'!$J$5:$J$500, MATCH(4, 'Vehicle Register'!$X$5:$X$500, 0)), "") -> 2AA-1047 | K8: =IFERROR(INDEX('Vehicle Register'!$K$5:$K$500, MATCH(4, 'Vehicle Register'!$X$5:$X$500, 0)), "") -> 46164 | L8: =IFERROR(INDEX('Vehicle Register'!$L$5:$L$500, MATCH(4, 'Vehicle Register'!$X$5:$X$500, 0)), "") -> 1450 | M8: =IFERROR(INDEX('Vehicle Register'!$M$5:$M$500, MATCH(4, 'Vehicle Register'!$X$5:$X$500, 0)), "") -> 0 | N8: =IFERROR(INDEX('Vehicle Register'!$N$5:$N$500, MATCH(4, 'Vehicle Register'!$X$5:$X$500, 0)), "") -> 1450 | O8: =IFERROR(INDEX('Vehicle Register'!$O$5:$O$500, MATCH(4, 'Vehicle Register'!$X$5:$X$500, 0)), "") -> Complete | P8: =IFERROR(INDEX('Vehicle Register'!$P$5:$P$500, MATCH(4, 'Vehicle Register'!$X$5:$X$500, 0)), "") -> 0 | Q8: =IFERROR(INDEX('Vehicle Register'!$Q$5:$Q$500, MATCH(4, 'Vehicle Register'!$X$5:$X$500, 0)), "") -> 1750 | R8: =IFERROR(INDEX('Vehicle Register'!$R$5:$R$500, MATCH(4, 'Vehicle Register'!$X$5:$X$500, 0)), "") -> 46183 | S8: =IFERROR(INDEX('Vehicle Register'!$S$5:$S$500, MATCH(4, 'Vehicle Register'!$X$5:$X$500, 0)), "") -> 1750 | T8: =IFERROR(INDEX('Vehicle Register'!$T$5:$T$500, MATCH(4, 'Vehicle Register'!$X$5:$X$500, 0)), "") -> 19 | U8: =IFERROR(INDEX('Vehicle Register'!$U$5:$U$500, MATCH(4, 'Vehicle Register'!$X$5:$X$500, 0)), "") -> 300 | V8: =IFERROR(INDEX('Vehicle Register'!$V$5:$V$500, MATCH(4, 'Vehicle Register'!$X$5:$X$500, 0)), "") -> 0.17142857 | W8: =IFERROR(INDEX('Vehicle Register'!$W$5:$W$500, MATCH(4, 'Vehicle Register'!$X$5:$X$500, 0)), "") -> 46174
A9: =IFERROR(INDEX('Vehicle Register'!$A$5:$A$500, MATCH(5, 'Vehicle Register'!$X$5:$X$500, 0)), "") -> RM-0005 | B9: =IFERROR(INDEX('Vehicle Register'!$B$5:$B$500, MATCH(5, 'Vehicle Register'!$X$5:$X$500, 0)), "") -> Sold | C9: =IFERROR(INDEX('Vehicle Register'!$C$5:$C$500, MATCH(5, 'Vehicle Register'!$X$5:$X$500, 0)), "") -> New | D9: =IFERROR(INDEX('Vehicle Register'!$D$5:$D$500, MATCH(5, 'Vehicle Register'!$X$5:$X$500, 0)), "") -> Honda | E9: =IFERROR(INDEX('Vehicle Register'!$E$5:$E$500, MATCH(5, 'Vehicle Register'!$X$5:$X$500, 0)), "") -> Honda Click 125i | F9: =IFERROR(INDEX('Vehicle Register'!$F$5:$F$500, MATCH(5, 'Vehicle Register'!$X$5:$X$500, 0)), "") -> 2026 | G9: =IFERROR(INDEX('Vehicle Register'!$G$5:$G$500, MATCH(5, 'Vehicle Register'!$X$5:$X$500, 0)), "") -> White | H9: =IFERROR(INDEX('Vehicle Register'!$H$5:$H$500, MATCH(5, 'Vehicle Register'!$X$5:$X$500, 0)), "") -> JF71E-330210 | I9: =IFERROR(INDEX('Vehicle Register'!$I$5:$I$500, MATCH(5, 'Vehicle Register'!$X$5:$X$500, 0)), "") -> MLHJF71E3P8330210 | J9: =IFERROR(INDEX('Vehicle Register'!$J$5:$J$500, MATCH(5, 'Vehicle Register'!$X$5:$X$500, 0)), "") -> 2AA-1058 | K9: =IFERROR(INDEX('Vehicle Register'!$K$5:$K$500, MATCH(5, 'Vehicle Register'!$X$5:$X$500, 0)), "") -> 46167 | L9: =IFERROR(INDEX('Vehicle Register'!$L$5:$L$500, MATCH(5, 'Vehicle Register'!$X$5:$X$500, 0)), "") -> 1750 | M9: =IFERROR(INDEX('Vehicle Register'!$M$5:$M$500, MATCH(5, 'Vehicle Register'!$X$5:$X$500, 0)), "") -> 0 | N9: =IFERROR(INDEX('Vehicle Register'!$N$5:$N$500, MATCH(5, 'Vehicle Register'!$X$5:$X$500, 0)), "") -> 1750 | O9: =IFERROR(INDEX('Vehicle Register'!$O$5:$O$500, MATCH(5, 'Vehicle Register'!$X$5:$X$500, 0)), "") -> Complete | P9: =IFERROR(INDEX('Vehicle Register'!$P$5:$P$500, MATCH(5, 'Vehicle Register'!$X$5:$X$500, 0)), "") -> 0 | Q9: =IFERROR(INDEX('Vehicle Register'!$Q$5:$Q$500, MATCH(5, 'Vehicle Register'!$X$5:$X$500, 0)), "") -> 2100 | R9: =IFERROR(INDEX('Vehicle Register'!$R$5:$R$500, MATCH(5, 'Vehicle Register'!$X$5:$X$500, 0)), "") -> 46191 | S9: =IFERROR(INDEX('Vehicle Register'!$S$5:$S$500, MATCH(5, 'Vehicle Register'!$X$5:$X$500, 0)), "") -> 2100 | T9: =IFERROR(INDEX('Vehicle Register'!$T$5:$T$500, MATCH(5, 'Vehicle Register'!$X$5:$X$500, 0)), "") -> 24 | U9: =IFERROR(INDEX('Vehicle Register'!$U$5:$U$500, MATCH(5, 'Vehicle Register'!$X$5:$X$500, 0)), "") -> 350 | V9: =IFERROR(INDEX('Vehicle Register'!$V$5:$V$500, MATCH(5, 'Vehicle Register'!$X$5:$X$500, 0)), "") -> 0.16666667 | W9: =IFERROR(INDEX('Vehicle Register'!$W$5:$W$500, MATCH(5, 'Vehicle Register'!$X$5:$X$500, 0)), "") -> 46174
A10: =IFERROR(INDEX('Vehicle Register'!$A$5:$A$500, MATCH(6, 'Vehicle Register'!$X$5:$X$500, 0)), "") -> RM-0006 | B10: =IFERROR(INDEX('Vehicle Register'!$B$5:$B$500, MATCH(6, 'Vehicle Register'!$X$5:$X$500, 0)), "") -> Sold | C10: =IFERROR(INDEX('Vehicle Register'!$C$5:$C$500, MATCH(6, 'Vehicle Register'!$X$5:$X$500, 0)), "") -> New | D10: =IFERROR(INDEX('Vehicle Register'!$D$5:$D$500, MATCH(6, 'Vehicle Register'!$X$5:$X$500, 0)), "") -> Honda | E10: =IFERROR(INDEX('Vehicle Register'!$E$5:$E$500, MATCH(6, 'Vehicle Register'!$X$5:$X$500, 0)), "") -> Honda Beat 110 | F10: =IFERROR(INDEX('Vehicle Register'!$F$5:$F$500, MATCH(6, 'Vehicle Register'!$X$5:$X$500, 0)), "") -> 2026 | G10: =IFERROR(INDEX('Vehicle Register'!$G$5:$G$500, MATCH(6, 'Vehicle Register'!$X$5:$X$500, 0)), "") -> Silver | H10: =IFERROR(INDEX('Vehicle Register'!$H$5:$H$500, MATCH(6, 'Vehicle Register'!$X$5:$X$500, 0)), "") -> JB02E-440310 | I10: =IFERROR(INDEX('Vehicle Register'!$I$5:$I$500, MATCH(6, 'Vehicle Register'!$X$5:$X$500, 0)), "") -> MLHJB02E4P8440310 | J10: =IFERROR(INDEX('Vehicle Register'!$J$5:$J$500, MATCH(6, 'Vehicle Register'!$X$5:$X$500, 0)), "") -> 2AA-1061 | K10: =IFERROR(INDEX('Vehicle Register'!$K$5:$K$500, MATCH(6, 'Vehicle Register'!$X$5:$X$500, 0)), "") -> 46170 | L10: =IFERROR(INDEX('Vehicle Register'!$L$5:$L$500, MATCH(6, 'Vehicle Register'!$X$5:$X$500, 0)), "") -> 1300 | M10: =IFERROR(INDEX('Vehicle Register'!$M$5:$M$500, MATCH(6, 'Vehicle Register'!$X$5:$X$500, 0)), "") -> 0 | N10: =IFERROR(INDEX('Vehicle Register'!$N$5:$N$500, MATCH(6, 'Vehicle Register'!$X$5:$X$500, 0)), "") -> 1300 | O10: =IFERROR(INDEX('Vehicle Register'!$O$5:$O$500, MATCH(6, 'Vehicle Register'!$X$5:$X$500, 0)), "") -> Complete | P10: =IFERROR(INDEX('Vehicle Register'!$P$5:$P$500, MATCH(6, 'Vehicle Register'!$X$5:$X$500, 0)), "") -> 0 | Q10: =IFERROR(INDEX('Vehicle Register'!$Q$5:$Q$500, MATCH(6, 'Vehicle Register'!$X$5:$X$500, 0)), "") -> 1600 | R10: =IFERROR(INDEX('Vehicle Register'!$R$5:$R$500, MATCH(6, 'Vehicle Register'!$X$5:$X$500, 0)), "") -> 46198 | S10: =IFERROR(INDEX('Vehicle Register'!$S$5:$S$500, MATCH(6, 'Vehicle Register'!$X$5:$X$500, 0)), "") -> 1600 | T10: =IFERROR(INDEX('Vehicle Register'!$T$5:$T$500, MATCH(6, 'Vehicle Register'!$X$5:$X$500, 0)), "") -> 28 | U10: =IFERROR(INDEX('Vehicle Register'!$U$5:$U$500, MATCH(6, 'Vehicle Register'!$X$5:$X$500, 0)), "") -> 300 | V10: =IFERROR(INDEX('Vehicle Register'!$V$5:$V$500, MATCH(6, 'Vehicle Register'!$X$5:$X$500, 0)), "") -> 0.1875 | W10: =IFERROR(INDEX('Vehicle Register'!$W$5:$W$500, MATCH(6, 'Vehicle Register'!$X$5:$X$500, 0)), "") -> 46174
A11: =IFERROR(INDEX('Vehicle Register'!$A$5:$A$500, MATCH(7, 'Vehicle Register'!$X$5:$X$500, 0)), "") -> RM-0007 | B11: =IFERROR(INDEX('Vehicle Register'!$B$5:$B$500, MATCH(7, 'Vehicle Register'!$X$5:$X$500, 0)), "") -> Sold | C11: =IFERROR(INDEX('Vehicle Register'!$C$5:$C$500, MATCH(7, 'Vehicle Register'!$X$5:$X$500, 0)), "") -> New | D11: =IFERROR(INDEX('Vehicle Register'!$D$5:$D$500, MATCH(7, 'Vehicle Register'!$X$5:$X$500, 0)), "") -> Honda | E11: =IFERROR(INDEX('Vehicle Register'!$E$5:$E$500, MATCH(7, 'Vehicle Register'!$X$5:$X$500, 0)), "") -> Honda Beat 110 | F11: =IFERROR(INDEX('Vehicle Register'!$F$5:$F$500, MATCH(7, 'Vehicle Register'!$X$5:$X$500, 0)), "") -> 2026 | G11: =IFERROR(INDEX('Vehicle Register'!$G$5:$G$500, MATCH(7, 'Vehicle Register'!$X$5:$X$500, 0)), "") -> Black | H11: =IFERROR(INDEX('Vehicle Register'!$H$5:$H$500, MATCH(7, 'Vehicle Register'!$X$5:$X$500, 0)), "") -> JB02E-440311 | I11: =IFERROR(INDEX('Vehicle Register'!$I$5:$I$500, MATCH(7, 'Vehicle Register'!$X$5:$X$500, 0)), "") -> MLHJB02E4P8440311 | J11: =IFERROR(INDEX('Vehicle Register'!$J$5:$J$500, MATCH(7, 'Vehicle Register'!$X$5:$X$500, 0)), "") -> 2AA-1062 | K11: =IFERROR(INDEX('Vehicle Register'!$K$5:$K$500, MATCH(7, 'Vehicle Register'!$X$5:$X$500, 0)), "") -> 46170 | L11: =IFERROR(INDEX('Vehicle Register'!$L$5:$L$500, MATCH(7, 'Vehicle Register'!$X$5:$X$500, 0)), "") -> 1300 | M11: =IFERROR(INDEX('Vehicle Register'!$M$5:$M$500, MATCH(7, 'Vehicle Register'!$X$5:$X$500, 0)), "") -> 0 | N11: =IFERROR(INDEX('Vehicle Register'!$N$5:$N$500, MATCH(7, 'Vehicle Register'!$X$5:$X$500, 0)), "") -> 1300 | O11: =IFERROR(INDEX('Vehicle Register'!$O$5:$O$500, MATCH(7, 'Vehicle Register'!$X$5:$X$500, 0)), "") -> Complete | P11: =IFERROR(INDEX('Vehicle Register'!$P$5:$P$500, MATCH(7, 'Vehicle Register'!$X$5:$X$500, 0)), "") -> 0 | Q11: =IFERROR(INDEX('Vehicle Register'!$Q$5:$Q$500, MATCH(7, 'Vehicle Register'!$X$5:$X$500, 0)), "") -> 1600 | R11: =IFERROR(INDEX('Vehicle Register'!$R$5:$R$500, MATCH(7, 'Vehicle Register'!$X$5:$X$500, 0)), "") -> 46198 | S11: =IFERROR(INDEX('Vehicle Register'!$S$5:$S$500, MATCH(7, 'Vehicle Register'!$X$5:$X$500, 0)), "") -> 1600 | T11: =IFERROR(INDEX('Vehicle Register'!$T$5:$T$500, MATCH(7, 'Vehicle Register'!$X$5:$X$500, 0)), "") -> 28 | U11: =IFERROR(INDEX('Vehicle Register'!$U$5:$U$500, MATCH(7, 'Vehicle Register'!$X$5:$X$500, 0)), "") -> 300 | V11: =IFERROR(INDEX('Vehicle Register'!$V$5:$V$500, MATCH(7, 'Vehicle Register'!$X$5:$X$500, 0)), "") -> 0.1875 | W11: =IFERROR(INDEX('Vehicle Register'!$W$5:$W$500, MATCH(7, 'Vehicle Register'!$X$5:$X$500, 0)), "") -> 46174
A12: =IFERROR(INDEX('Vehicle Register'!$A$5:$A$500, MATCH(8, 'Vehicle Register'!$X$5:$X$500, 0)), "") -> RM-0008 | B12: =IFERROR(INDEX('Vehicle Register'!$B$5:$B$500, MATCH(8, 'Vehicle Register'!$X$5:$X$500, 0)), "") -> Sold | C12: =IFERROR(INDEX('Vehicle Register'!$C$5:$C$500, MATCH(8, 'Vehicle Register'!$X$5:$X$500, 0)), "") -> New | D12: =IFERROR(INDEX('Vehicle Register'!$D$5:$D$500, MATCH(8, 'Vehicle Register'!$X$5:$X$500, 0)), "") -> Honda | E12: =IFERROR(INDEX('Vehicle Register'!$E$5:$E$500, MATCH(8, 'Vehicle Register'!$X$5:$X$500, 0)), "") -> Honda Scoopy i | F12: =IFERROR(INDEX('Vehicle Register'!$F$5:$F$500, MATCH(8, 'Vehicle Register'!$X$5:$X$500, 0)), "") -> 2026 | G12: =IFERROR(INDEX('Vehicle Register'!$G$5:$G$500, MATCH(8, 'Vehicle Register'!$X$5:$X$500, 0)), "") -> White | H12: =IFERROR(INDEX('Vehicle Register'!$H$5:$H$500, MATCH(8, 'Vehicle Register'!$X$5:$X$500, 0)), "") -> JC30E-550402 | I12: =IFERROR(INDEX('Vehicle Register'!$I$5:$I$500, MATCH(8, 'Vehicle Register'!$X$5:$X$500, 0)), "") -> MLHJC30E5P8550402 | J12: =IFERROR(INDEX('Vehicle Register'!$J$5:$J$500, MATCH(8, 'Vehicle Register'!$X$5:$X$500, 0)), "") -> 2AA-1070 | K12: =IFERROR(INDEX('Vehicle Register'!$K$5:$K$500, MATCH(8, 'Vehicle Register'!$X$5:$X$500, 0)), "") -> 46174 | L12: =IFERROR(INDEX('Vehicle Register'!$L$5:$L$500, MATCH(8, 'Vehicle Register'!$X$5:$X$500, 0)), "") -> 1600 | M12: =IFERROR(INDEX('Vehicle Register'!$M$5:$M$500, MATCH(8, 'Vehicle Register'!$X$5:$X$500, 0)), "") -> 0 | N12: =IFERROR(INDEX('Vehicle Register'!$N$5:$N$500, MATCH(8, 'Vehicle Register'!$X$5:$X$500, 0)), "") -> 1600 | O12: =IFERROR(INDEX('Vehicle Register'!$O$5:$O$500, MATCH(8, 'Vehicle Register'!$X$5:$X$500, 0)), "") -> Complete | P12: =IFERROR(INDEX('Vehicle Register'!$P$5:$P$500, MATCH(8, 'Vehicle Register'!$X$5:$X$500, 0)), "") -> 0 | Q12: =IFERROR(INDEX('Vehicle Register'!$Q$5:$Q$500, MATCH(8, 'Vehicle Register'!$X$5:$X$500, 0)), "") -> 1950 | R12: =IFERROR(INDEX('Vehicle Register'!$R$5:$R$500, MATCH(8, 'Vehicle Register'!$X$5:$X$500, 0)), "") -> 46205 | S12: =IFERROR(INDEX('Vehicle Register'!$S$5:$S$500, MATCH(8, 'Vehicle Register'!$X$5:$X$500, 0)), "") -> 1950 | T12: =IFERROR(INDEX('Vehicle Register'!$T$5:$T$500, MATCH(8, 'Vehicle Register'!$X$5:$X$500, 0)), "") -> 31 | U12: =IFERROR(INDEX('Vehicle Register'!$U$5:$U$500, MATCH(8, 'Vehicle Register'!$X$5:$X$500, 0)), "") -> 350 | V12: =IFERROR(INDEX('Vehicle Register'!$V$5:$V$500, MATCH(8, 'Vehicle Register'!$X$5:$X$500, 0)), "") -> 0.17948718 | W12: =IFERROR(INDEX('Vehicle Register'!$W$5:$W$500, MATCH(8, 'Vehicle Register'!$X$5:$X$500, 0)), "") -> 46204
A13: =IFERROR(INDEX('Vehicle Register'!$A$5:$A$500, MATCH(9, 'Vehicle Register'!$X$5:$X$500, 0)), "") -> RM-0009 | B13: =IFERROR(INDEX('Vehicle Register'!$B$5:$B$500, MATCH(9, 'Vehicle Register'!$X$5:$X$500, 0)), "") -> Sold | C13: =IFERROR(INDEX('Vehicle Register'!$C$5:$C$500, MATCH(9, 'Vehicle Register'!$X$5:$X$500, 0)), "") -> New | D13: =IFERROR(INDEX('Vehicle Register'!$D$5:$D$500, MATCH(9, 'Vehicle Register'!$X$5:$X$500, 0)), "") -> Honda | E13: =IFERROR(INDEX('Vehicle Register'!$E$5:$E$500, MATCH(9, 'Vehicle Register'!$X$5:$X$500, 0)), "") -> Honda Scoopy i | F13: =IFERROR(INDEX('Vehicle Register'!$F$5:$F$500, MATCH(9, 'Vehicle Register'!$X$5:$X$500, 0)), "") -> 2026 | G13: =IFERROR(INDEX('Vehicle Register'!$G$5:$G$500, MATCH(9, 'Vehicle Register'!$X$5:$X$500, 0)), "") -> Pink | H13: =IFERROR(INDEX('Vehicle Register'!$H$5:$H$500, MATCH(9, 'Vehicle Register'!$X$5:$X$500, 0)), "") -> JC30E-550403 | I13: =IFERROR(INDEX('Vehicle Register'!$I$5:$I$500, MATCH(9, 'Vehicle Register'!$X$5:$X$500, 0)), "") -> MLHJC30E5P8550403 | J13: =IFERROR(INDEX('Vehicle Register'!$J$5:$J$500, MATCH(9, 'Vehicle Register'!$X$5:$X$500, 0)), "") -> 2AA-1071 | K13: =IFERROR(INDEX('Vehicle Register'!$K$5:$K$500, MATCH(9, 'Vehicle Register'!$X$5:$X$500, 0)), "") -> 46174 | L13: =IFERROR(INDEX('Vehicle Register'!$L$5:$L$500, MATCH(9, 'Vehicle Register'!$X$5:$X$500, 0)), "") -> 1600 | M13: =IFERROR(INDEX('Vehicle Register'!$M$5:$M$500, MATCH(9, 'Vehicle Register'!$X$5:$X$500, 0)), "") -> 0 | N13: =IFERROR(INDEX('Vehicle Register'!$N$5:$N$500, MATCH(9, 'Vehicle Register'!$X$5:$X$500, 0)), "") -> 1600 | O13: =IFERROR(INDEX('Vehicle Register'!$O$5:$O$500, MATCH(9, 'Vehicle Register'!$X$5:$X$500, 0)), "") -> Complete | P13: =IFERROR(INDEX('Vehicle Register'!$P$5:$P$500, MATCH(9, 'Vehicle Register'!$X$5:$X$500, 0)), "") -> 0 | Q13: =IFERROR(INDEX('Vehicle Register'!$Q$5:$Q$500, MATCH(9, 'Vehicle Register'!$X$5:$X$500, 0)), "") -> 1950 | R13: =IFERROR(INDEX('Vehicle Register'!$R$5:$R$500, MATCH(9, 'Vehicle Register'!$X$5:$X$500, 0)), "") -> 46205 | S13: =IFERROR(INDEX('Vehicle Register'!$S$5:$S$500, MATCH(9, 'Vehicle Register'!$X$5:$X$500, 0)), "") -> 1950 | T13: =IFERROR(INDEX('Vehicle Register'!$T$5:$T$500, MATCH(9, 'Vehicle Register'!$X$5:$X$500, 0)), "") -> 31 | U13: =IFERROR(INDEX('Vehicle Register'!$U$5:$U$500, MATCH(9, 'Vehicle Register'!$X$5:$X$500, 0)), "") -> 350 | V13: =IFERROR(INDEX('Vehicle Register'!$V$5:$V$500, MATCH(9, 'Vehicle Register'!$X$5:$X$500, 0)), "") -> 0.17948718 | W13: =IFERROR(INDEX('Vehicle Register'!$W$5:$W$500, MATCH(9, 'Vehicle Register'!$X$5:$X$500, 0)), "") -> 46204
A14: =IFERROR(INDEX('Vehicle Register'!$A$5:$A$500, MATCH(10, 'Vehicle Register'!$X$5:$X$500, 0)), "") -> RM-0010 | B14: =IFERROR(INDEX('Vehicle Register'!$B$5:$B$500, MATCH(10, 'Vehicle Register'!$X$5:$X$500, 0)), "") -> Sold | C14: =IFERROR(INDEX('Vehicle Register'!$C$5:$C$500, MATCH(10, 'Vehicle Register'!$X$5:$X$500, 0)), "") -> New | D14: =IFERROR(INDEX('Vehicle Register'!$D$5:$D$500, MATCH(10, 'Vehicle Register'!$X$5:$X$500, 0)), "") -> Honda | E14: =IFERROR(INDEX('Vehicle Register'!$E$5:$E$500, MATCH(10, 'Vehicle Register'!$X$5:$X$500, 0)), "") -> Honda Future 125 | F14: =IFERROR(INDEX('Vehicle Register'!$F$5:$F$500, MATCH(10, 'Vehicle Register'!$X$5:$X$500, 0)), "") -> 2026 | G14: =IFERROR(INDEX('Vehicle Register'!$G$5:$G$500, MATCH(10, 'Vehicle Register'!$X$5:$X$500, 0)), "") -> Blue | H14: =IFERROR(INDEX('Vehicle Register'!$H$5:$H$500, MATCH(10, 'Vehicle Register'!$X$5:$X$500, 0)), "") -> JD44E-660512 | I14: =IFERROR(INDEX('Vehicle Register'!$I$5:$I$500, MATCH(10, 'Vehicle Register'!$X$5:$X$500, 0)), "") -> MLHJD44E6P8660512 | J14: =IFERROR(INDEX('Vehicle Register'!$J$5:$J$500, MATCH(10, 'Vehicle Register'!$X$5:$X$500, 0)), "") -> 2AA-1080 | K14: =IFERROR(INDEX('Vehicle Register'!$K$5:$K$500, MATCH(10, 'Vehicle Register'!$X$5:$X$500, 0)), "") -> 46176 | L14: =IFERROR(INDEX('Vehicle Register'!$L$5:$L$500, MATCH(10, 'Vehicle Register'!$X$5:$X$500, 0)), "") -> 1580 | M14: =IFERROR(INDEX('Vehicle Register'!$M$5:$M$500, MATCH(10, 'Vehicle Register'!$X$5:$X$500, 0)), "") -> 0 | N14: =IFERROR(INDEX('Vehicle Register'!$N$5:$N$500, MATCH(10, 'Vehicle Register'!$X$5:$X$500, 0)), "") -> 1580 | O14: =IFERROR(INDEX('Vehicle Register'!$O$5:$O$500, MATCH(10, 'Vehicle Register'!$X$5:$X$500, 0)), "") -> Complete | P14: =IFERROR(INDEX('Vehicle Register'!$P$5:$P$500, MATCH(10, 'Vehicle Register'!$X$5:$X$500, 0)), "") -> 0 | Q14: =IFERROR(INDEX('Vehicle Register'!$Q$5:$Q$500, MATCH(10, 'Vehicle Register'!$X$5:$X$500, 0)), "") -> 1900 | R14: =IFERROR(INDEX('Vehicle Register'!$R$5:$R$500, MATCH(10, 'Vehicle Register'!$X$5:$X$500, 0)), "") -> 46212 | S14: =IFERROR(INDEX('Vehicle Register'!$S$5:$S$500, MATCH(10, 'Vehicle Register'!$X$5:$X$500, 0)), "") -> 1900 | T14: =IFERROR(INDEX('Vehicle Register'!$T$5:$T$500, MATCH(10, 'Vehicle Register'!$X$5:$X$500, 0)), "") -> 36 | U14: =IFERROR(INDEX('Vehicle Register'!$U$5:$U$500, MATCH(10, 'Vehicle Register'!$X$5:$X$500, 0)), "") -> 320 | V14: =IFERROR(INDEX('Vehicle Register'!$V$5:$V$500, MATCH(10, 'Vehicle Register'!$X$5:$X$500, 0)), "") -> 0.16842105 | W14: =IFERROR(INDEX('Vehicle Register'!$W$5:$W$500, MATCH(10, 'Vehicle Register'!$X$5:$X$500, 0)), "") -> 46204
A15: =IFERROR(INDEX('Vehicle Register'!$A$5:$A$500, MATCH(11, 'Vehicle Register'!$X$5:$X$500, 0)), "") -> RM-0014 | B15: =IFERROR(INDEX('Vehicle Register'!$B$5:$B$500, MATCH(11, 'Vehicle Register'!$X$5:$X$500, 0)), "") -> Sold | C15: =IFERROR(INDEX('Vehicle Register'!$C$5:$C$500, MATCH(11, 'Vehicle Register'!$X$5:$X$500, 0)), "") -> New | D15: =IFERROR(INDEX('Vehicle Register'!$D$5:$D$500, MATCH(11, 'Vehicle Register'!$X$5:$X$500, 0)), "") -> Yamaha | E15: =IFERROR(INDEX('Vehicle Register'!$E$5:$E$500, MATCH(11, 'Vehicle Register'!$X$5:$X$500, 0)), "") -> Yamaha NMAX 155 | F15: =IFERROR(INDEX('Vehicle Register'!$F$5:$F$500, MATCH(11, 'Vehicle Register'!$X$5:$X$500, 0)), "") -> 2026 | G15: =IFERROR(INDEX('Vehicle Register'!$G$5:$G$500, MATCH(11, 'Vehicle Register'!$X$5:$X$500, 0)), "") -> Gray | H15: =IFERROR(INDEX('Vehicle Register'!$H$5:$H$500, MATCH(11, 'Vehicle Register'!$X$5:$X$500, 0)), "") -> 2DP-005521 | I15: =IFERROR(INDEX('Vehicle Register'!$I$5:$I$500, MATCH(11, 'Vehicle Register'!$X$5:$X$500, 0)), "") -> MH32DP005TK005521 | J15: =IFERROR(INDEX('Vehicle Register'!$J$5:$J$500, MATCH(11, 'Vehicle Register'!$X$5:$X$500, 0)), "") -> 2AA-1102 | K15: =IFERROR(INDEX('Vehicle Register'!$K$5:$K$500, MATCH(11, 'Vehicle Register'!$X$5:$X$500, 0)), "") -> 46185 | L15: =IFERROR(INDEX('Vehicle Register'!$L$5:$L$500, MATCH(11, 'Vehicle Register'!$X$5:$X$500, 0)), "") -> 3050 | M15: =IFERROR(INDEX('Vehicle Register'!$M$5:$M$500, MATCH(11, 'Vehicle Register'!$X$5:$X$500, 0)), "") -> 0 | N15: =IFERROR(INDEX('Vehicle Register'!$N$5:$N$500, MATCH(11, 'Vehicle Register'!$X$5:$X$500, 0)), "") -> 3050 | O15: =IFERROR(INDEX('Vehicle Register'!$O$5:$O$500, MATCH(11, 'Vehicle Register'!$X$5:$X$500, 0)), "") -> Complete | P15: =IFERROR(INDEX('Vehicle Register'!$P$5:$P$500, MATCH(11, 'Vehicle Register'!$X$5:$X$500, 0)), "") -> 0 | Q15: =IFERROR(INDEX('Vehicle Register'!$Q$5:$Q$500, MATCH(11, 'Vehicle Register'!$X$5:$X$500, 0)), "") -> 3600 | R15: =IFERROR(INDEX('Vehicle Register'!$R$5:$R$500, MATCH(11, 'Vehicle Register'!$X$5:$X$500, 0)), "") -> 46225 | S15: =IFERROR(INDEX('Vehicle Register'!$S$5:$S$500, MATCH(11, 'Vehicle Register'!$X$5:$X$500, 0)), "") -> 3600 | T15: =IFERROR(INDEX('Vehicle Register'!$T$5:$T$500, MATCH(11, 'Vehicle Register'!$X$5:$X$500, 0)), "") -> 40 | U15: =IFERROR(INDEX('Vehicle Register'!$U$5:$U$500, MATCH(11, 'Vehicle Register'!$X$5:$X$500, 0)), "") -> 550 | V15: =IFERROR(INDEX('Vehicle Register'!$V$5:$V$500, MATCH(11, 'Vehicle Register'!$X$5:$X$500, 0)), "") -> 0.15277778 | W15: =IFERROR(INDEX('Vehicle Register'!$W$5:$W$500, MATCH(11, 'Vehicle Register'!$X$5:$X$500, 0)), "") -> 46204
A16: =IFERROR(INDEX('Vehicle Register'!$A$5:$A$500, MATCH(12, 'Vehicle Register'!$X$5:$X$500, 0)), "") -> RM-0017 | B16: =IFERROR(INDEX('Vehicle Register'!$B$5:$B$500, MATCH(12, 'Vehicle Register'!$X$5:$X$500, 0)), "") -> Sold | C16: =IFERROR(INDEX('Vehicle Register'!$C$5:$C$500, MATCH(12, 'Vehicle Register'!$X$5:$X$500, 0)), "") -> New | D16: =IFERROR(INDEX('Vehicle Register'!$D$5:$D$500, MATCH(12, 'Vehicle Register'!$X$5:$X$500, 0)), "") -> Honda | E16: =IFERROR(INDEX('Vehicle Register'!$E$5:$E$500, MATCH(12, 'Vehicle Register'!$X$5:$X$500, 0)), "") -> Honda Air Blade 125 | F16: =IFERROR(INDEX('Vehicle Register'!$F$5:$F$500, MATCH(12, 'Vehicle Register'!$X$5:$X$500, 0)), "") -> 2026 | G16: =IFERROR(INDEX('Vehicle Register'!$G$5:$G$500, MATCH(12, 'Vehicle Register'!$X$5:$X$500, 0)), "") -> Matte Black | H16: =IFERROR(INDEX('Vehicle Register'!$H$5:$H$500, MATCH(12, 'Vehicle Register'!$X$5:$X$500, 0)), "") -> JG10E-770601 | I16: =IFERROR(INDEX('Vehicle Register'!$I$5:$I$500, MATCH(12, 'Vehicle Register'!$X$5:$X$500, 0)), "") -> MLHJG10E7P8770601 | J16: =IFERROR(INDEX('Vehicle Register'!$J$5:$J$500, MATCH(12, 'Vehicle Register'!$X$5:$X$500, 0)), "") -> 2AA-1130 | K16: =IFERROR(INDEX('Vehicle Register'!$K$5:$K$500, MATCH(12, 'Vehicle Register'!$X$5:$X$500, 0)), "") -> 46204 | L16: =IFERROR(INDEX('Vehicle Register'!$L$5:$L$500, MATCH(12, 'Vehicle Register'!$X$5:$X$500, 0)), "") -> 2050 | M16: =IFERROR(INDEX('Vehicle Register'!$M$5:$M$500, MATCH(12, 'Vehicle Register'!$X$5:$X$500, 0)), "") -> 0 | N16: =IFERROR(INDEX('Vehicle Register'!$N$5:$N$500, MATCH(12, 'Vehicle Register'!$X$5:$X$500, 0)), "") -> 2050 | O16: =IFERROR(INDEX('Vehicle Register'!$O$5:$O$500, MATCH(12, 'Vehicle Register'!$X$5:$X$500, 0)), "") -> Complete | P16: =IFERROR(INDEX('Vehicle Register'!$P$5:$P$500, MATCH(12, 'Vehicle Register'!$X$5:$X$500, 0)), "") -> 0 | Q16: =IFERROR(INDEX('Vehicle Register'!$Q$5:$Q$500, MATCH(12, 'Vehicle Register'!$X$5:$X$500, 0)), "") -> 2450 | R16: =IFERROR(INDEX('Vehicle Register'!$R$5:$R$500, MATCH(12, 'Vehicle Register'!$X$5:$X$500, 0)), "") -> 46238 | S16: =IFERROR(INDEX('Vehicle Register'!$S$5:$S$500, MATCH(12, 'Vehicle Register'!$X$5:$X$500, 0)), "") -> 2450 | T16: =IFERROR(INDEX('Vehicle Register'!$T$5:$T$500, MATCH(12, 'Vehicle Register'!$X$5:$X$500, 0)), "") -> 34 | U16: =IFERROR(INDEX('Vehicle Register'!$U$5:$U$500, MATCH(12, 'Vehicle Register'!$X$5:$X$500, 0)), "") -> 400 | V16: =IFERROR(INDEX('Vehicle Register'!$V$5:$V$500, MATCH(12, 'Vehicle Register'!$X$5:$X$500, 0)), "") -> 0.16326531 | W16: =IFERROR(INDEX('Vehicle Register'!$W$5:$W$500, MATCH(12, 'Vehicle Register'!$X$5:$X$500, 0)), "") -> 46235
A17: =IFERROR(INDEX('Vehicle Register'!$A$5:$A$500, MATCH(13, 'Vehicle Register'!$X$5:$X$500, 0)), "") -> RM-0018 | B17: =IFERROR(INDEX('Vehicle Register'!$B$5:$B$500, MATCH(13, 'Vehicle Register'!$X$5:$X$500, 0)), "") -> Sold | C17: =IFERROR(INDEX('Vehicle Register'!$C$5:$C$500, MATCH(13, 'Vehicle Register'!$X$5:$X$500, 0)), "") -> New | D17: =IFERROR(INDEX('Vehicle Register'!$D$5:$D$500, MATCH(13, 'Vehicle Register'!$X$5:$X$500, 0)), "") -> Honda | E17: =IFERROR(INDEX('Vehicle Register'!$E$5:$E$500, MATCH(13, 'Vehicle Register'!$X$5:$X$500, 0)), "") -> Honda Click 125i | F17: =IFERROR(INDEX('Vehicle Register'!$F$5:$F$500, MATCH(13, 'Vehicle Register'!$X$5:$X$500, 0)), "") -> 2026 | G17: =IFERROR(INDEX('Vehicle Register'!$G$5:$G$500, MATCH(13, 'Vehicle Register'!$X$5:$X$500, 0)), "") -> Red | H17: =IFERROR(INDEX('Vehicle Register'!$H$5:$H$500, MATCH(13, 'Vehicle Register'!$X$5:$X$500, 0)), "") -> JF71E-330211 | I17: =IFERROR(INDEX('Vehicle Register'!$I$5:$I$500, MATCH(13, 'Vehicle Register'!$X$5:$X$500, 0)), "") -> MLHJF71E3P8330211 | J17: =IFERROR(INDEX('Vehicle Register'!$J$5:$J$500, MATCH(13, 'Vehicle Register'!$X$5:$X$500, 0)), "") -> 2AA-1141 | K17: =IFERROR(INDEX('Vehicle Register'!$K$5:$K$500, MATCH(13, 'Vehicle Register'!$X$5:$X$500, 0)), "") -> 46206 | L17: =IFERROR(INDEX('Vehicle Register'!$L$5:$L$500, MATCH(13, 'Vehicle Register'!$X$5:$X$500, 0)), "") -> 1750 | M17: =IFERROR(INDEX('Vehicle Register'!$M$5:$M$500, MATCH(13, 'Vehicle Register'!$X$5:$X$500, 0)), "") -> 0 | N17: =IFERROR(INDEX('Vehicle Register'!$N$5:$N$500, MATCH(13, 'Vehicle Register'!$X$5:$X$500, 0)), "") -> 1750 | O17: =IFERROR(INDEX('Vehicle Register'!$O$5:$O$500, MATCH(13, 'Vehicle Register'!$X$5:$X$500, 0)), "") -> Complete | P17: =IFERROR(INDEX('Vehicle Register'!$P$5:$P$500, MATCH(13, 'Vehicle Register'!$X$5:$X$500, 0)), "") -> 0 | Q17: =IFERROR(INDEX('Vehicle Register'!$Q$5:$Q$500, MATCH(13, 'Vehicle Register'!$X$5:$X$500, 0)), "") -> 2100 | R17: =IFERROR(INDEX('Vehicle Register'!$R$5:$R$500, MATCH(13, 'Vehicle Register'!$X$5:$X$500, 0)), "") -> 46245 | S17: =IFERROR(INDEX('Vehicle Register'!$S$5:$S$500, MATCH(13, 'Vehicle Register'!$X$5:$X$500, 0)), "") -> 2100 | T17: =IFERROR(INDEX('Vehicle Register'!$T$5:$T$500, MATCH(13, 'Vehicle Register'!$X$5:$X$500, 0)), "") -> 39 | U17: =IFERROR(INDEX('Vehicle Register'!$U$5:$U$500, MATCH(13, 'Vehicle Register'!$X$5:$X$500, 0)), "") -> 350 | V17: =IFERROR(INDEX('Vehicle Register'!$V$5:$V$500, MATCH(13, 'Vehicle Register'!$X$5:$X$500, 0)), "") -> 0.16666667 | W17: =IFERROR(INDEX('Vehicle Register'!$W$5:$W$500, MATCH(13, 'Vehicle Register'!$X$5:$X$500, 0)), "") -> 46235
A18: =IFERROR(INDEX('Vehicle Register'!$A$5:$A$500, MATCH(14, 'Vehicle Register'!$X$5:$X$500, 0)), "") -> RM-0019 | B18: =IFERROR(INDEX('Vehicle Register'!$B$5:$B$500, MATCH(14, 'Vehicle Register'!$X$5:$X$500, 0)), "") -> Sold | C18: =IFERROR(INDEX('Vehicle Register'!$C$5:$C$500, MATCH(14, 'Vehicle Register'!$X$5:$X$500, 0)), "") -> New | D18: =IFERROR(INDEX('Vehicle Register'!$D$5:$D$500, MATCH(14, 'Vehicle Register'!$X$5:$X$500, 0)), "") -> Honda | E18: =IFERROR(INDEX('Vehicle Register'!$E$5:$E$500, MATCH(14, 'Vehicle Register'!$X$5:$X$500, 0)), "") -> Honda Click 125i | F18: =IFERROR(INDEX('Vehicle Register'!$F$5:$F$500, MATCH(14, 'Vehicle Register'!$X$5:$X$500, 0)), "") -> 2026 | G18: =IFERROR(INDEX('Vehicle Register'!$G$5:$G$500, MATCH(14, 'Vehicle Register'!$X$5:$X$500, 0)), "") -> Black | H18: =IFERROR(INDEX('Vehicle Register'!$H$5:$H$500, MATCH(14, 'Vehicle Register'!$X$5:$X$500, 0)), "") -> JF71E-330212 | I18: =IFERROR(INDEX('Vehicle Register'!$I$5:$I$500, MATCH(14, 'Vehicle Register'!$X$5:$X$500, 0)), "") -> MLHJF71E3P8330212 | J18: =IFERROR(INDEX('Vehicle Register'!$J$5:$J$500, MATCH(14, 'Vehicle Register'!$X$5:$X$500, 0)), "") -> 2AA-1142 | K18: =IFERROR(INDEX('Vehicle Register'!$K$5:$K$500, MATCH(14, 'Vehicle Register'!$X$5:$X$500, 0)), "") -> 46206 | L18: =IFERROR(INDEX('Vehicle Register'!$L$5:$L$500, MATCH(14, 'Vehicle Register'!$X$5:$X$500, 0)), "") -> 1750 | M18: =IFERROR(INDEX('Vehicle Register'!$M$5:$M$500, MATCH(14, 'Vehicle Register'!$X$5:$X$500, 0)), "") -> 0 | N18: =IFERROR(INDEX('Vehicle Register'!$N$5:$N$500, MATCH(14, 'Vehicle Register'!$X$5:$X$500, 0)), "") -> 1750 | O18: =IFERROR(INDEX('Vehicle Register'!$O$5:$O$500, MATCH(14, 'Vehicle Register'!$X$5:$X$500, 0)), "") -> Complete | P18: =IFERROR(INDEX('Vehicle Register'!$P$5:$P$500, MATCH(14, 'Vehicle Register'!$X$5:$X$500, 0)), "") -> 0 | Q18: =IFERROR(INDEX('Vehicle Register'!$Q$5:$Q$500, MATCH(14, 'Vehicle Register'!$X$5:$X$500, 0)), "") -> 2100 | R18: =IFERROR(INDEX('Vehicle Register'!$R$5:$R$500, MATCH(14, 'Vehicle Register'!$X$5:$X$500, 0)), "") -> 46245 | S18: =IFERROR(INDEX('Vehicle Register'!$S$5:$S$500, MATCH(14, 'Vehicle Register'!$X$5:$X$500, 0)), "") -> 2100 | T18: =IFERROR(INDEX('Vehicle Register'!$T$5:$T$500, MATCH(14, 'Vehicle Register'!$X$5:$X$500, 0)), "") -> 39 | U18: =IFERROR(INDEX('Vehicle Register'!$U$5:$U$500, MATCH(14, 'Vehicle Register'!$X$5:$X$500, 0)), "") -> 350 | V18: =IFERROR(INDEX('Vehicle Register'!$V$5:$V$500, MATCH(14, 'Vehicle Register'!$X$5:$X$500, 0)), "") -> 0.16666667 | W18: =IFERROR(INDEX('Vehicle Register'!$W$5:$W$500, MATCH(14, 'Vehicle Register'!$X$5:$X$500, 0)), "") -> 46235
